<sdf version='1.7'>
  <world name='default'>
    <gravity>0 0 -9.8</gravity>
    <magnetic_field>6e-06 2.3e-05 -4.2e-05</magnetic_field>
    <atmosphere type='adiabatic'/>
    <physics type='ode'>
      <max_step_size>0.001</max_step_size>
      <real_time_factor>1</real_time_factor>
      <real_time_update_rate>1000</real_time_update_rate>
    </physics>
    <scene>
      <ambient>0.4 0.4 0.4 1</ambient>
      <background>0.7 0.7 0.7 1</background>
      <shadows>1</shadows>
    </scene>
    <audio>
      <device>default</device>
    </audio>
    <wind/>
    <spherical_coordinates>
      <surface_model>EARTH_WGS84</surface_model>
      <latitude_deg>0</latitude_deg>
      <longitude_deg>0</longitude_deg>
      <elevation>0</elevation>
      <heading_deg>0</heading_deg>
    </spherical_coordinates>
    <model name='my_bot'>
      <link name='base_link'>
        <inertial>
          <pose>-0.04277 0 0.032436 0 -0 0</pose>
          <mass>0.51</mass>
          <inertia>
            <ixx>0.000495641</ixx>
            <ixy>0</ixy>
            <ixz>-9.27968e-06</ixz>
            <iyy>0.000643728</iyy>
            <iyz>0</iyz>
            <izz>0.00112485</izz>
          </inertia>
        </inertial>
        <collision name='base_link_fixed_joint_lump__caster_wheel_collision'>
          <pose>-0.08 0 0.008 0 -0 0</pose>
          <geometry>
            <sphere>
              <radius>0.008</radius>
            </sphere>
          </geometry>
          <surface>
            <contact>
              <ode/>
            </contact>
            <friction>
              <ode>
                <mu>0.001</mu>
                <mu2>0.001</mu2>
              </ode>
              <torsional>
                <ode/>
              </torsional>
            </friction>
            <bounce/>
          </surface>
          <max_contacts>10</max_contacts>
        </collision>
        <collision name='base_link_fixed_joint_lump__chassis_collision_1'>
          <pose>-0.042025 0 0.032925 0 -0 0</pose>
          <geometry>
            <box>
              <size>0.1222 0.10825 0.005</size>
            </box>
          </geometry>
          <surface>
            <contact>
              <ode/>
            </contact>
            <friction>
              <ode/>
              <torsional>
                <ode/>
              </torsional>
            </friction>
            <bounce/>
          </surface>
          <max_contacts>10</max_contacts>
        </collision>
        <visual name='base_link_fixed_joint_lump__caster_wheel_visual'>
          <pose>-0.08 0 0.008 0 -0 0</pose>
          <geometry>
            <sphere>
              <radius>0.008</radius>
            </sphere>
          </geometry>
          <material>
            <script>
              <name>Gazebo/Black</name>
              <uri>file://media/materials/scripts/gazebo.material</uri>
            </script>
          </material>
        </visual>
        <visual name='base_link_fixed_joint_lump__chassis_visual_1'>
          <pose>-0.042025 0 0.032925 0 -0 0</pose>
          <geometry>
            <box>
              <size>0.1222 0.10825 0.005</size>
            </box>
          </geometry>
          <material>
            <script>
              <name>Gazebo/White</name>
              <uri>file://media/materials/scripts/gazebo.material</uri>
            </script>
          </material>
        </visual>
        <self_collide>0</self_collide>
        <enable_wind>0</enable_wind>
        <kinematic>0</kinematic>
      </link>
      <joint name='left_wheel_joint' type='revolute'>
        <pose relative_to='base_link'>0 0.0675 0.02175 -1.5708 0 0</pose>
        <parent>base_link</parent>
        <child>left_wheel</child>
        <axis>
          <xyz>0 0 1</xyz>
          <limit>
            <lower>-1e+16</lower>
            <upper>1e+16</upper>
          </limit>
          <dynamics>
            <spring_reference>0</spring_reference>
            <spring_stiffness>0</spring_stiffness>
          </dynamics>
        </axis>
      </joint>
      <link name='left_wheel'>
        <pose relative_to='left_wheel_joint'>0 0 0 0 -0 0</pose>
        <inertial>
          <pose>0 0 0 0 -0 0</pose>
          <mass>0.05</mass>
          <inertia>
            <ixx>6.25078e-06</ixx>
            <ixy>0</ixy>
            <ixz>0</ixz>
            <iyy>6.25078e-06</iyy>
            <iyz>0</iyz>
            <izz>1.18266e-05</izz>
          </inertia>
        </inertial>
        <collision name='left_wheel_collision'>
          <pose>0 0 0 0 -0 0</pose>
          <geometry>
            <cylinder>
              <length>0.009</length>
              <radius>0.02175</radius>
            </cylinder>
          </geometry>
          <surface>
            <contact>
              <ode/>
            </contact>
            <friction>
              <ode/>
              <torsional>
                <ode/>
              </torsional>
            </friction>
            <bounce/>
          </surface>
          <max_contacts>10</max_contacts>
        </collision>
        <visual name='left_wheel_visual'>
          <pose>0 0 0 0 -0 0</pose>
          <geometry>
            <cylinder>
              <length>0.009</length>
              <radius>0.02175</radius>
            </cylinder>
          </geometry>
          <material>
            <script>
              <name>Gazebo/Black</name>
              <uri>file://media/materials/scripts/gazebo.material</uri>
            </script>
          </material>
        </visual>
        <self_collide>0</self_collide>
        <enable_wind>0</enable_wind>
        <kinematic>0</kinematic>
      </link>
      <joint name='right_wheel_joint' type='revolute'>
        <pose relative_to='base_link'>0 -0.0675 0.02175 1.5708 -0 0</pose>
        <parent>base_link</parent>
        <child>right_wheel</child>
        <axis>
          <xyz>0 0 -1</xyz>
          <limit>
            <lower>-1e+16</lower>
            <upper>1e+16</upper>
          </limit>
          <dynamics>
            <spring_reference>0</spring_reference>
            <spring_stiffness>0</spring_stiffness>
          </dynamics>
        </axis>
      </joint>
      <link name='right_wheel'>
        <pose relative_to='right_wheel_joint'>0 0 0 0 -0 0</pose>
        <inertial>
          <pose>0 0 0 0 -0 0</pose>
          <mass>0.05</mass>
          <inertia>
            <ixx>6.25078e-06</ixx>
            <ixy>0</ixy>
            <ixz>0</ixz>
            <iyy>6.25078e-06</iyy>
            <iyz>0</iyz>
            <izz>1.18266e-05</izz>
          </inertia>
        </inertial>
        <collision name='right_wheel_collision'>
          <pose>0 0 0 0 -0 0</pose>
          <geometry>
            <cylinder>
              <length>0.009</length>
              <radius>0.02175</radius>
            </cylinder>
          </geometry>
          <surface>
            <contact>
              <ode/>
            </contact>
            <friction>
              <ode/>
              <torsional>
                <ode/>
              </torsional>
            </friction>
            <bounce/>
          </surface>
          <max_contacts>10</max_contacts>
        </collision>
        <visual name='right_wheel_visual'>
          <pose>0 0 0 0 -0 0</pose>
          <geometry>
            <cylinder>
              <length>0.009</length>
              <radius>0.02175</radius>
            </cylinder>
          </geometry>
          <material>
            <script>
              <name>Gazebo/Black</name>
              <uri>file://media/materials/scripts/gazebo.material</uri>
            </script>
          </material>
        </visual>
        <self_collide>0</self_collide>
        <enable_wind>0</enable_wind>
        <kinematic>0</kinematic>
      </link>
      <static>0</static>
      <plugin name='gazebo_ros2_control' filename='libgazebo_ros2_control.so'>
        <parameters>/home/ice/dev_ws/install/mek_lilrobot/share/mek_lilrobot/config/controllers.yaml</parameters>
      </plugin>
      <pose>0 0 0 0 -0 0</pose>
    </model>
    <model name='my_model'>
      <pose>1.05636 -1.09125 0.5 0 -0 0</pose>
      <static>1</static>
      <link name='link'>
        <collision name='collision'>
          <geometry>
            <mesh>
              <uri>/home/ice/.gazebo/models/mek_arena/arena.obj</uri>
            </mesh>
          </geometry>
          <max_contacts>10</max_contacts>
          <surface>
            <contact>
              <ode/>
            </contact>
            <bounce/>
            <friction>
              <torsional>
                <ode/>
              </torsional>
              <ode/>
            </friction>
          </surface>
        </collision>
        <visual name='visual'>
          <geometry>
            <mesh>
              <uri>/home/ice/.gazebo/models/mek_arena/arena.obj</uri>
            </mesh>
          </geometry>
        </visual>
        <self_collide>0</self_collide>
        <enable_wind>0</enable_wind>
        <kinematic>0</kinematic>
      </link>
    </model>
    <light name='user_point_light_0' type='point'>
      <pose>-0.012999 -0.002477 1 0 -0 0</pose>
      <diffuse>0.5 0.5 0.5 1</diffuse>
      <specular>0.1 0.1 0.1 1</specular>
      <attenuation>
        <range>20</range>
        <constant>0.5</constant>
        <linear>0.01</linear>
        <quadratic>0.001</quadratic>
      </attenuation>
      <cast_shadows>0</cast_shadows>
      <direction>0 0 -1</direction>
    </light>
    <state world_name='default'>
      <sim_time>463 913000000</sim_time>
      <real_time>511 227851218</real_time>
      <wall_time>1680125009 232318920</wall_time>
      <iterations>463913</iterations>
      <model name='my_bot'>
        <pose>0.352843 -0.254496 -5e-06 -7e-05 -0.000124 1.5635</pose>
        <scale>1 1 1</scale>
        <link name='base_link'>
          <pose>0.352843 -0.254496 -5e-06 -7e-05 -0.000124 1.5635</pose>
          <velocity>1.4e-05 0.001813 -1e-06 0.055994 -0.000409 0.000198</velocity>
          <acceleration>-0.000979 -0.14433 -5.77757 -2.81147 -1.07872 -1.13968</acceleration>
          <wrench>-0.000499 -0.073608 -2.94656 0 -0 0</wrench>
        </link>
        <link name='left_wheel'>
          <pose>0.285344 -0.254006 0.021741 1.57099 -0.017055 -1.57809</pose>
          <velocity>3e-06 0.000582 -1e-06 -0.026728 0.000566 0.000179</velocity>
          <acceleration>0.008577 1.30109 -0.000228 2.54 0.166878 -0.089218</acceleration>
          <wrench>0.000429 0.065054 -1.1e-05 0 -0 0</wrench>
        </link>
        <link name='right_wheel'>
          <pose>0.420339 -0.254991 0.02175 1.57096 1.28019 1.56367</pose>
          <velocity>7e-06 0.000608 -1e-06 -0.027993 -8.4e-05 0.0002</velocity>
          <acceleration>0.012385 1.29601 8.9e-05 1.86914 -0.487811 -0.044942</acceleration>
          <wrench>0.000619 0.064801 4e-06 0 -0 0</wrench>
        </link>
      </model>
      <model name='my_model'>
        <pose>0 0 0 0 -0 0</pose>
        <scale>1 1 1</scale>
        <link name='link'>
          <pose>0 0 0 0 -0 0</pose>
          <velocity>0 0 0 0 -0 0</velocity>
          <acceleration>0 0 0 0 -0 0</acceleration>
          <wrench>0 0 0 0 -0 0</wrench>
        </link>
      </model>
      <light name='user_point_light_0'>
        <pose>-0.069927 -0.065681 0.541695 0 -0 0</pose>
      </light>
    </state>
    <gui fullscreen='0'>
      <camera name='user_camera'>
        <pose>-0.960237 2.07429 1.3087 0 0.605798 -1.03978</pose>
        <view_controller>orbit</view_controller>
        <projection_type>perspective</projection_type>
      </camera>
    </gui>
  </world>
</sdf>
