<?xml version="1.0"?>
<robot xmlns:xacro="http://www.ros.org/wiki/xacro">

    <xacro:include filename="inertial_macros.xacro"/>

    <material name="white">
        <color rgba="1 1 1 1" />
    </material>

    <material name="black">
        <color rgba="0 0 0 1" />
    </material>

    <link name="base_link">

    </link>

    <joint name="chassis_joint" type="fixed">
        <parent link="base_link" />
        <child link="chassis" />
        <origin xyz="-0.042025 0 0.032925" />
    </joint>

    <link name="chassis">
        <visual>
            <geometry>
                <box size="0.1222 0.10825 0.005" />
            </geometry>
            <material name="white" />
        </visual>
        <collision>
            <geometry>
                <box size="0.1222 0.10825 0.005" />
            </geometry>
        </collision>
        <xacro:inertial_box mass="0.5" x="0.1222" y="0.10825" z="0.005">
            <origin xyz="0 0 0" rpy="0 0 0" />
        </xacro:inertial_box>
    </link>

    <gazebo reference="chassis">
        <material>Gazebo/White</material>
    </gazebo>



    <joint name="right_wheel_joint" type="continuous">
        <parent link="base_link" />
        <child link="right_wheel" />
        <origin rpy="1.570796 0 0" xyz="0 -0.0675 0.02175" />
        <axis xyz="0 0 -1" />
    </joint>

    <link name="right_wheel">
        <visual>
            <geometry>
                <cylinder radius="0.02175" length="0.009"/>
            </geometry>
            <material name="black"/>
        </visual>
        <collision>
            <geometry>
                <cylinder radius="0.02175" length="0.009"/>
            </geometry>
        </collision>
        <xacro:inertial_cylinder mass="0.05" radius="0.02175" length="0.009">
            <origin xyz="0 0 0" rpy="0 0 0"/>
        </xacro:inertial_cylinder>
    </link>

    <gazebo reference="right_wheel">
        <material>Gazebo/Black</material>
    </gazebo>

    <joint name="left_wheel_joint" type="continuous">
        <parent link="base_link" />
        <child link="left_wheel" />
        <origin rpy="-1.570796 0 0" xyz="0 0.0675 0.02175" />
        <axis xyz="0 0 1" />
    </joint>

    <link name="left_wheel">
        <visual>
            <geometry>
                <cylinder radius="0.02175" length="0.009"/>
            </geometry>
            <material name="black"/>
        </visual>
        <collision>
            <geometry>
                <cylinder radius="0.02175" length="0.009"/>
            </geometry>
        </collision>
        <xacro:inertial_cylinder mass="0.05" radius="0.02175" length="0.009">
            <origin xyz="0 0 0" rpy="0 0 0"/>
        </xacro:inertial_cylinder>
    </link>

    <gazebo reference="left_wheel">
        <material>Gazebo/Black</material>
    </gazebo>
    
    <joint name="caster_wheel_joint" type="fixed">
        <parent link="base_link"/>
        <child link="caster_wheel"/>
        <origin xyz="-0.080 0 0.008"/>
    </joint>

    <link name="caster_wheel">
        <visual>
            <geometry>
                <sphere radius="0.008"/>
            </geometry>
            <material name="black"/>
        </visual>
        <collision>
            <geometry>
                <sphere radius="0.008"/>
            </geometry>
        </collision>
        <xacro:inertial_sphere mass="0.01" radius="0.008">
            <origin xyz="0 0 0" rpy="0 0 0"/>
        </xacro:inertial_sphere>
    </link>

    
    <gazebo reference="caster_wheel">
        <material>Gazebo/Black</material>
        <mu1 value="0.001"/>
        <mu2 value="0.001"/>
    </gazebo>

</robot>